<?xml version="1.0" encoding="utf-8"?>
<!-- This URDF was automatically created by SolidWorks to URDF Exporter! Originally created by Stephen Brawner (brawner@gmail.com) 
     Commit Version: 1.6.0-4-g7f85cfe  Build Version: 1.6.7995.38578
     For more information, please see http://wiki.ros.org/sw_urdf_exporter -->
<robot
  name="Wheel_Mobile_Manipulator_URDF">
  <link
    name="Frame_Base">
    <inertial>
      <origin
        xyz="-0.220404256533912 4.34746524103843E-06 -0.149453443848564"
        rpy="0 0 0" />
      <mass
        value="24.9710693002439" />
      <inertia
        ixx="0.866944097756702"
        ixy="-2.49854830059428E-07"
        ixz="-0.0453643188615285"
        iyy="1.63760882672819"
        iyz="-1.90642963664106E-06"
        izz="2.34244361023883" />
    </inertial>
    <visual>
      <origin
        xyz="0 0 0"
        rpy="0 0 0" />
      <geometry>
        <mesh
          filename="package://Wheel_Mobile_Manipulator_URDF/meshes/Frame_Base.STL" />
      </geometry>
      <material
        name="">
        <color
          rgba="0.780392156862745 0.780392156862745 0.780392156862745 1" />
      </material>
    </visual>
    <collision>
      <origin
        xyz="0 0 0"
        rpy="0 0 0" />
      <geometry>
        <mesh
          filename="package://Wheel_Mobile_Manipulator_URDF/meshes/Frame_Base.STL" />
      </geometry>
    </collision>
  </link>
  <link
    name="Link1">
    <inertial>
      <origin
        xyz="-1.9665E-06 0.0098032 -0.053926"
        rpy="0 0 0" />
      <mass
        value="0.50842" />
      <inertia
        ixx="0.00070025"
        ixy="-2.0097E-08"
        ixz="-2.1013E-08"
        iyy="0.00082733"
        iyz="-7.3525E-05"
        izz="0.00048924" />
    </inertial>
    <visual>
      <origin
        xyz="0 0 0"
        rpy="0 0 0" />
      <geometry>
        <mesh
          filename="package://Wheel_Mobile_Manipulator_URDF/meshes/Link1.STL" />
      </geometry>
      <material
        name="">
        <color
          rgba="0.75294 0.75294 0.75294 1" />
      </material>
    </visual>
    <collision>
      <origin
        xyz="0 0 0"
        rpy="0 0 0" />
      <geometry>
        <mesh
          filename="package://Wheel_Mobile_Manipulator_URDF/meshes/Link1.STL" />
      </geometry>
    </collision>
  </link>
  <joint
    name="Joint1"
    type="continuous">
    <origin
      xyz="0 0 0.2848"
      rpy="0 0 0" />
    <parent
      link="Frame_Base" />
    <child
      link="Link1" />
    <axis
      xyz="0 0 1" />
    <limit
      lower="0"
      upper="0"
      effort="0"
      velocity="0" />
  </joint>
  <link
    name="Link2">
    <inertial>
      <origin
        xyz="-1.8401E-06 0.098847 0.0067744"
        rpy="0 0 0" />
      <mass
        value="0.4394" />
      <inertia
        ixx="0.00061344"
        ixy="-6.7995E-08"
        ixz="-2.0931E-08"
        iyy="0.00038571"
        iyz="6.3857E-05"
        izz="0.00069568" />
    </inertial>
    <visual>
      <origin
        xyz="0 0 0"
        rpy="0 0 0" />
      <geometry>
        <mesh
          filename="package://Wheel_Mobile_Manipulator_URDF/meshes/Link2.STL" />
      </geometry>
      <material
        name="">
        <color
          rgba="0.75294 0.75294 0.75294 1" />
      </material>
    </visual>
    <collision>
      <origin
        xyz="0 0 0"
        rpy="0 0 0" />
      <geometry>
        <mesh
          filename="package://Wheel_Mobile_Manipulator_URDF/meshes/Link2.STL" />
      </geometry>
    </collision>
  </link>
  <joint
    name="Joint2"
    type="revolute">
    <origin
      xyz="0 -0.0118 0"
      rpy="1.5708 0 0" />
    <parent
      link="Link1" />
    <child
      link="Link2" />
    <axis
      xyz="0 0 1" />
    <limit
      lower="-2.1991"
      upper="2.1991"
      effort="0"
      velocity="0" />
  </joint>
  <link
    name="Link3">
    <inertial>
      <origin
        xyz="-1.8393E-06 0.0066885 -0.094371"
        rpy="0 0 0" />
      <mass
        value="0.43861" />
      <inertia
        ixx="0.0012102"
        ixy="-8.1153E-09"
        ixz="5.895E-08"
        iyy="0.001291"
        iyz="-7.8769E-05"
        izz="0.00038569" />
    </inertial>
    <visual>
      <origin
        xyz="0 0 0"
        rpy="0 0 0" />
      <geometry>
        <mesh
          filename="package://Wheel_Mobile_Manipulator_URDF/meshes/Link3.STL" />
      </geometry>
      <material
        name="">
        <color
          rgba="0.75294 0.75294 0.75294 1" />
      </material>
    </visual>
    <collision>
      <origin
        xyz="0 0 0"
        rpy="0 0 0" />
      <geometry>
        <mesh
          filename="package://Wheel_Mobile_Manipulator_URDF/meshes/Link3.STL" />
      </geometry>
    </collision>
  </link>
  <joint
    name="Joint3"
    type="continuous">
    <origin
      xyz="0 0.4208 0"
      rpy="-1.5708 0 0" />
    <parent
      link="Link2" />
    <child
      link="Link3" />
    <axis
      xyz="0 0 1" />
    <limit
      lower="0"
      upper="0"
      effort="0"
      velocity="0" />
  </joint>
  <link
    name="Link4">
    <inertial>
      <origin
        xyz="2.4068E-06 0.076204 0.0082337"
        rpy="0 0 0" />
      <mass
        value="0.35461" />
      <inertia
        ixx="0.0004959"
        ixy="5.9288E-08"
        ixz="7.472E-10"
        iyy="0.00022825"
        iyz="5.7801E-05"
        izz="0.00057365" />
    </inertial>
    <visual>
      <origin
        xyz="0 0 0"
        rpy="0 0 0" />
      <geometry>
        <mesh
          filename="package://Wheel_Mobile_Manipulator_URDF/meshes/Link4.STL" />
      </geometry>
      <material
        name="">
        <color
          rgba="0.75294 0.75294 0.75294 1" />
      </material>
    </visual>
    <collision>
      <origin
        xyz="0 0 0"
        rpy="0 0 0" />
      <geometry>
        <mesh
          filename="package://Wheel_Mobile_Manipulator_URDF/meshes/Link4.STL" />
      </geometry>
    </collision>
  </link>
  <joint
    name="Joint4"
    type="revolute">
    <origin
      xyz="0 -0.0128 0"
      rpy="1.5708 0 0" />
    <parent
      link="Link3" />
    <child
      link="Link4" />
    <axis
      xyz="0 0 1" />
    <limit
      lower="-2.5656"
      upper="2.5656"
      effort="0"
      velocity="0" />
  </joint>
  <link
    name="Link5">
    <inertial>
      <origin
        xyz="-3.2453E-06 0.0092573 -0.042922"
        rpy="0 0 0" />
      <mass
        value="0.25083" />
      <inertia
        ixx="0.00019933"
        ixy="-1.363E-08"
        ixz="-4.4692E-08"
        iyy="0.00021608"
        iyz="-2.2091E-05"
        izz="0.00013443" />
    </inertial>
    <visual>
      <origin
        xyz="0 0 0"
        rpy="0 0 0" />
      <geometry>
        <mesh
          filename="package://Wheel_Mobile_Manipulator_URDF/meshes/Link5.STL" />
      </geometry>
      <material
        name="">
        <color
          rgba="0.75294 0.75294 0.75294 1" />
      </material>
    </visual>
    <collision>
      <origin
        xyz="0 0 0"
        rpy="0 0 0" />
      <geometry>
        <mesh
          filename="package://Wheel_Mobile_Manipulator_URDF/meshes/Link5.STL" />
      </geometry>
    </collision>
  </link>
  <joint
    name="Joint5"
    type="continuous">
    <origin
      xyz="0 0.3143 0"
      rpy="-1.5708 0 0" />
    <parent
      link="Link4" />
    <child
      link="Link5" />
    <axis
      xyz="0 0 1" />
    <limit
      lower="0"
      upper="0"
      effort="0"
      velocity="0" />
  </joint>
  <link
    name="Link6">
    <inertial>
      <origin
        xyz="-1.7292E-06 0.045401 0.009232"
        rpy="0 0 0" />
      <mass
        value="0.25081" />
      <inertia
        ixx="0.00021275"
        ixy="1.2745E-08"
        ixz="-5.3343E-09"
        iyy="0.00013776"
        iyz="3.0165E-05"
        izz="0.00022615" />
    </inertial>
    <visual>
      <origin
        xyz="0 0 0"
        rpy="0 0 0" />
      <geometry>
        <mesh
          filename="package://Wheel_Mobile_Manipulator_URDF/meshes/Link6.STL" />
      </geometry>
      <material
        name="">
        <color
          rgba="0.75294 0.75294 0.75294 1" />
      </material>
    </visual>
    <collision>
      <origin
        xyz="0 0 0"
        rpy="0 0 0" />
      <geometry>
        <mesh
          filename="package://Wheel_Mobile_Manipulator_URDF/meshes/Link6.STL" />
      </geometry>
    </collision>
  </link>
  <joint
    name="Joint6"
    type="revolute">
    <origin
      xyz="0 0 0"
      rpy="1.5708 0 0" />
    <parent
      link="Link5" />
    <child
      link="Link6" />
    <axis
      xyz="0 0 1" />
    <limit
      lower="-2.042"
      upper="2.042"
      effort="0"
      velocity="0" />
  </joint>
  <link
    name="Link7">
    <inertial>
      <origin
        xyz="-0.00014216 0.0088091 0.13293"
        rpy="0 0 0" />
      <mass
        value="0.16126" />
      <inertia
        ixx="6.5041E-05"
        ixy="1.0089E-07"
        ixz="3.2323E-07"
        iyy="8.0848E-05"
        iyz="1.7333E-07"
        izz="0.00010703" />
    </inertial>
    <visual>
      <origin
        xyz="0 0 0"
        rpy="0 0 0" />
      <geometry>
        <mesh
          filename="package://Wheel_Mobile_Manipulator_URDF/meshes/Link7.STL" />
      </geometry>
      <material
        name="">
        <color
          rgba="0.75294 0.75294 0.75294 1" />
      </material>
    </visual>
    <collision>
      <origin
        xyz="0 0 0"
        rpy="0 0 0" />
      <geometry>
        <mesh
          filename="package://Wheel_Mobile_Manipulator_URDF/meshes/Link7.STL" />
      </geometry>
    </collision>
  </link>
  <joint
    name="Joint7"
    type="continuous">
    <origin
      xyz="0 0 0"
      rpy="-1.5708 0 0" />
    <parent
      link="Link6" />
    <child
      link="Link7" />
    <axis
      xyz="0 0 1" />
    <limit
      lower="0"
      upper="0"
      effort="0"
      velocity="0" />
  </joint>
  <link
    name="Link_Rear1">
    <inertial>
      <origin
        xyz="-0.023595 5.4088E-08 -0.028362"
        rpy="0 0 0" />
      <mass
        value="0.045082" />
      <inertia
        ixx="2.1663E-05"
        ixy="-1.5812E-11"
        ixz="-1.2714E-05"
        iyy="3.3958E-05"
        iyz="-5.028E-12"
        izz="2.4439E-05" />
    </inertial>
    <visual>
      <origin
        xyz="0 0 0"
        rpy="0 0 0" />
      <geometry>
        <mesh
          filename="package://Wheel_Mobile_Manipulator_URDF/meshes/Link_Rear1.STL" />
      </geometry>
      <material
        name="">
        <color
          rgba="0.84314 0.81569 0.75294 1" />
      </material>
    </visual>
    <collision>
      <origin
        xyz="0 0 0"
        rpy="0 0 0" />
      <geometry>
        <mesh
          filename="package://Wheel_Mobile_Manipulator_URDF/meshes/Link_Rear1.STL" />
      </geometry>
    </collision>
  </link>
  <joint
    name="Joint_Rear1"
    type="continuous">
    <origin
      xyz="-0.5 0 -0.31"
      rpy="0 0 0" />
    <parent
      link="Frame_Base" />
    <child
      link="Link_Rear1" />
    <axis
      xyz="0 0 1" />
    <limit
      lower="0"
      upper="0"
      effort="0"
      velocity="0" />
  </joint>
  <link
    name="Link_Rear2">
    <inertial>
      <origin
        xyz="-1.1102E-16 1.1102E-16 -0.015"
        rpy="0 0 0" />
      <mass
        value="0.033157" />
      <inertia
        ixx="8.7716E-06"
        ixy="1.4781E-21"
        ixz="1.2707E-22"
        iyy="8.7716E-06"
        iyz="-4.9526E-23"
        izz="1.6122E-05" />
    </inertial>
    <visual>
      <origin
        xyz="0 0 0"
        rpy="0 0 0" />
      <geometry>
        <mesh
          filename="package://Wheel_Mobile_Manipulator_URDF/meshes/Link_Rear2.STL" />
      </geometry>
      <material
        name="">
        <color
          rgba="0.63137 0.65882 0.67843 1" />
      </material>
    </visual>
    <collision>
      <origin
        xyz="0 0 0"
        rpy="0 0 0" />
      <geometry>
        <mesh
          filename="package://Wheel_Mobile_Manipulator_URDF/meshes/Link_Rear2.STL" />
      </geometry>
    </collision>
  </link>
  <joint
    name="Joint_Rear2"
    type="continuous">
    <origin
      xyz="-0.05 -0.015 -0.06"
      rpy="1.5708 0 0" />
    <parent
      link="Link_Rear1" />
    <child
      link="Link_Rear2" />
    <axis
      xyz="0 0 1" />
    <limit
      lower="0"
      upper="0"
      effort="0"
      velocity="0" />
  </joint>
  <link
    name="Link_Wheel_Left">
    <inertial>
      <origin
        xyz="-1.1102E-16 -2.2204E-16 0.025"
        rpy="0 0 0" />
      <mass
        value="1.1169" />
      <inertia
        ixx="0.0035999"
        ixy="1.6527E-19"
        ixz="-9.691E-21"
        iyy="0.0035999"
        iyz="-1.3118E-19"
        izz="0.0067919" />
    </inertial>
    <visual>
      <origin
        xyz="0 0 0"
        rpy="0 0 0" />
      <geometry>
        <mesh
          filename="package://Wheel_Mobile_Manipulator_URDF/meshes/Link_Wheel_Left.STL" />
      </geometry>
      <material
        name="">
        <color
          rgba="0.63137 0.65882 0.67843 1" />
      </material>
    </visual>
    <collision>
      <origin
        xyz="0 0 0"
        rpy="0 0 0" />
      <geometry>
        <mesh
          filename="package://Wheel_Mobile_Manipulator_URDF/meshes/Link_Wheel_Left.STL" />
      </geometry>
    </collision>
  </link>
  <joint
    name="Joint_Wheel_Left"
    type="continuous">
    <origin
      xyz="0 0.275 -0.3"
      rpy="1.5708 0 0" />
    <parent
      link="Frame_Base" />
    <child
      link="Link_Wheel_Left" />
    <axis
      xyz="0 0 1" />
    <limit
      lower="0"
      upper="0"
      effort="0"
      velocity="0" />
  </joint>
  <link
    name="Link_Wheel_Right">
    <inertial>
      <origin
        xyz="-6.6613E-16 3.3307E-16 -0.025"
        rpy="0 0 0" />
      <mass
        value="1.1169" />
      <inertia
        ixx="0.0035999"
        ixy="3.3935E-19"
        ixz="-2.4029E-20"
        iyy="0.0035999"
        iyz="-3.291E-19"
        izz="0.0067919" />
    </inertial>
    <visual>
      <origin
        xyz="0 0 0"
        rpy="0 0 0" />
      <geometry>
        <mesh
          filename="package://Wheel_Mobile_Manipulator_URDF/meshes/Link_Wheel_Right.STL" />
      </geometry>
      <material
        name="">
        <color
          rgba="0.63137 0.65882 0.67843 1" />
      </material>
    </visual>
    <collision>
      <origin
        xyz="0 0 0"
        rpy="0 0 0" />
      <geometry>
        <mesh
          filename="package://Wheel_Mobile_Manipulator_URDF/meshes/Link_Wheel_Right.STL" />
      </geometry>
    </collision>
  </link>
  <joint
    name="Joint_Wheel_Right"
    type="continuous">
    <origin
      xyz="0 -0.275 -0.3"
      rpy="1.5708 0 0" />
    <parent
      link="Frame_Base" />
    <child
      link="Link_Wheel_Right" />
    <axis
      xyz="0 0 1" />
    <limit
      lower="0"
      upper="0"
      effort="0"
      velocity="0" />
  </joint>
</robot>